Workbook

Sheet Registrar Ponto
A1: REGISTRO DE PONTO — DATATEMPO/CP2
A4: IDENTIFICAÇÃO E LANÇAMENTO
A6: Número/ID
A8: Pessoa
A9: Situação atual
A10: Tipo de registro
A12: Projeto
A14: Atividade
A16: Observação
A19: RETORNO | C19: REGISTRO REALIZADO COM SUCESSO. PAINEL LIMPO PARA O PRÓXIMO USUÁRIO.
A22: COMO USAR: selecione o ID, escolha INÍCIO ou FIM, informe o projeto e a atividade padronizados e clique em REGISTRAR. Para encerrar, mantenha o mesmo projeto e a mesma atividade usados no início.

Sheet Cadastro Pessoas
A1: CADASTRO DE PESSOAS
A2: Cadastro expansível para até 100 pessoas. Preencha uma linha vazia da tabela, use ID único e status ATIVO.
A4: ID | B4: Pessoa | C4: Base | D4: R$/h útil | E4: R$/h FDS | F4: R$/diária | G4: Função/Regra | H4: Status
A5: 1001 | B5: Adriana Pereira dos Santos | C5: Hora | D5: 17 | E5: 20 | F5: 0 | G5: Supervisão | H5: ATIVO
A6: 1002 | B6: Alex de Almeida Mariano | C6: Hora | D6: 23.5 | E6: 23.5 | F6: 0 | G6: Analista/Revisor | H6: ATIVO
A7: 1003 | B7: Amanda do Carmo Ribeiro | C7: Hora | D7: 23.5 | E7: 23.5 | F7: 0 | G7: Analista de Pesquisa Júnior | H7: ATIVO
A8: 1004 | B8: Angela Bertoli | C8: Hora | D8: 21.5 | E8: 20 | F8: 0 | G8: Coordenação/Supervisão | H8: ATIVO
A9: 1005 | B9: Carolina Fantini Vidigal Diniz Dias | C9: Hora | D9: 13 | E9: 16.5 | F9: 0 | G9: Assistente de Pesquisa | H9: ATIVO
A10: 1006 | B10: Eliane dos Santos Oliveira | C10: Hora | D10: 14 | E10: 17 | F10: 0 | G10: Checagem | H10: ATIVO
A11: 1007 | B11: Fernanda Lopes | C11: Hora | D11: 23.5 | E11: 23.5 | F11: 0 | G11: Assistente de Pesquisa — confirmar taxa | H11: ATIVO
A12: 1008 | B12: Flávia Reis | C12: Hora | D12: 14 | E12: 17 | F12: 0 | G12: Checagem | H12: ATIVO
A13: 1009 | B13: Junia Maria Santos | C13: Hora | D13: 14 | E13: 17 | F13: 0 | G13: Checagem | H13: ATIVO
A14: 1010 | B14: Nataly Tayê | C14: Hora | D14: 14 | E14: 17 | F14: 0 | G14: Checagem | H14: ATIVO
A15: 1011 | B15: Nathalia Arruda | C15: Hora | D15: 23.5 | E15: 23.5 | F15: 0 | G15: Analista | H15: ATIVO
A16: 1012 | B16: Nelma Lucia dos S. B. Brandão | C16: Diária | D16: 0 | E16: 0 | F16: 222.72 | G16: Apoio/Checagem | H16: ATIVO
... A21: 1017 | B21: Renato Inácio da Silva | C21: Hora | D21: 14 | E21: 17 | F21: 0 | G21: Checagem | H21: ATIVO

Sheet Cadastro Projetos
A1: CADASTRO PADRONIZADO DE PROJETOS
A2: Cadastro expansível para até 150 projetos. Código e nome devem ser únicos; use status ATIVO.
A4: Código | B4: Projeto padronizado | C4: Descrição | D4: Status
A5: PRJ-001 | B5: BC - CONFIANÇA PIX | C5: Banco Central do Brasil | D5: ATIVO
A6: PRJ-002 | B6: CFI / ACCION | C6: MAP II MSE Demand — São Paulo | D6: ATIVO
A7: PRJ-003 | B7: SICOOB CREDICOM | C7: Tracking de Marca | D7: ATIVO
A8: PRJ-004 | B8: OTEMPO | C8: Imagem, percepção e reputação | D8: ATIVO
A9: PRJ-005 | B9: ESTADUAL - OTEMPO | C9: Pesquisas eleitorais e tracking | D9: ATIVO
A10: PRJ-006 | B10: CDL/BH | C10: Pesquisas de levantamento do comércio | D10: ATIVO
A11: PRJ-007 | B11: TOOLKIT | C11: Projetos Toolkit | D11: ATIVO
A12: PRJ-008 | B12: CAMPANHA | C12: Pesquisa Prof. Luiz Felizardo | D12: ATIVO
A13: PRJ-009 | B13: ADMINISTRATIVO | C13: Atividades administrativas internas | D13: ATIVO
A14: PRJ-010 | B14: OUTROS | C14: Usar apenas após autorização | D14: ATIVO
A15: PRJ-011 | B15: BETIM - TRACKING | C15: pesquisa de levantamento eleitoral VM | D15: ATIVO

Sheet Cadastro Atividades
A1: CADASTRO PADRONIZADO DE ATIVIDADES
A2: Cadastro expansível para até 200 atividades. Código e nome devem ser únicos; use status ATIVO.
A4: Código | B4: Atividade padronizada | C4: Descrição | D4: Status
A5: ATV-001 | B5: SUPERVISÃO | C5: Coordenação e supervisão operacional | D5: ATIVO
A6: ATV-002 | B6: CHECAGEM | C6: Checagem e controle de qualidade | D6: ATIVO
A7: ATV-003 | B7: CODIFICAÇÃO | C7: Codificação de respostas | D7: ATIVO
A8: ATV-004 | B8: ANÁLISE | C8: Análise estatística ou qualitativa | D8: ATIVO
A9: ATV-005 | B9: RECRUTAMENTO | C9: Recrutamento de participantes | D9: ATIVO
A10: ATV-006 | B10: APLICAÇÃO / ENTREVISTA | C10: Aplicação de questionários ou entrevistas | D10: ATIVO
A11: ATV-007 | B11: TRATAMENTO DE DADOS | C11: Limpeza, crítica, harmonização ou ETL | D11: ATIVO
A12: ATV-008 | B12: RELATÓRIO | C12: Redação, revisão ou apresentação de resultados | D12: ATIVO
A13: ATV-009 | B13: ADMINISTRATIVO | C13: Rotinas administrativas e financeiras | D13: ATIVO
A14: ATV-010 | B14: APOIO OPERACIONAL | C14: Apoio geral à operação | D14: ATIVO
A15: ATV-011 | B15: TRANSCRIÇÃO | C15: Transcrição de Entrevistas e Grupos de Discussão | D15: ATIVO
A16: ATV-012 | B16: MODERAÇÃO | C16: Moderação de EP e GD | D16: ATIVO

Sheet Batidas
A1: BATIDAS — TRILHA DE AUDITORIA
A2: Cada clique em REGISTRAR gera uma batida imutável nesta tabela.
A4: Batida ID | B4: Data e hora | C4: Data | D4: Dia da semana | E4: ID | F4: Pessoa | G4: Tipo | H4: Projeto | I4: Atividade | J4: Observação | K4: Origem
A6: B20260825152719-1001 | B6: 46259.644 | C6: 46259 | D6: TERÇA-FEIRA | E6: 1001 | F6: Adriana Pereira dos Santos | G6: INÍCIO | H6: SICOOB CREDICOM | I6: SUPERVISÃO | K6: SharePoint / Office Script
A7: B20260825153010-1001 | B7: 46259.646 | C7: 46259 | D7: TERÇA-FEIRA | E7: 1001 | F7: Adriana Pereira dos Santos | G7: FIM | H7: SICOOB CREDICOM | I7: SUPERVISÃO | J7: supervisão e checagem | K7: SharePoint / Office Script
A8: B20260825161730-1015 | B8: 46259.679 | C8: 46259 | D8: TERÇA-FEIRA | E8: 1015 | F8: Vitor Guilherme Miguel Rocha | G8: INÍCIO | H8: ADMINISTRATIVO | I8: ADMINISTRATIVO | K8: SharePoint / Office Script
A9: B20260825161753-1015 | B9: 46259.679 | C9: 46259 | D9: TERÇA-FEIRA | E9: 1015 | F9: Vitor Guilherme Miguel Rocha | G9: INÍCIO | H9: ADMINISTRATIVO | I9: ADMINISTRATIVO | K9: SharePoint / Office Script
A10: B20260825161841-1015 | B10: 46259.68 | C10: 46259 | D10: TERÇA-FEIRA | E10: 1015 | F10: Vitor Guilherme Miguel Rocha | G10: INÍCIO | H10: ADMINISTRATIVO | I10: ADMINISTRATIVO | K10: SharePoint / Office Script
A11: B20260825161948-1015 | B11: 46259.68 | C11: 46259 | D11: TERÇA-FEIRA | E11: 1015 | F11: Vitor Guilherme Miguel Rocha | G11: INÍCIO | H11: ADMINISTRATIVO | I11: ADMINISTRATIVO | K11: SharePoint / Office Script
A12: B20260825162022-1015 | B12: 46259.681 | C12: 46259 | D12: TERÇA-FEIRA | E12: 1015 | F12: Vitor Guilherme Miguel Rocha | G12: INÍCIO | H12: ADMINISTRATIVO | I12: ADMINISTRATIVO | K12: SharePoint / Office Script
A13: B20260825162049-1015 | B13: 46259.681 | C13: 46259 | D13: TERÇA-FEIRA | E13: 1015 | F13: Vitor Guilherme Miguel Rocha | G13: FIM | H13: ADMINISTRATIVO | I13: ADMINISTRATIVO | K13: SharePoint / Office Script
A14: B20260825162622-1001 | B14: 46259.685 | C14: 46259 | D14: TERÇA-FEIRA | E14: 1001 | F14: Adriana Pereira dos Santos | G14: INÍCIO | H14: ESTADUAL - OTEMPO | I14: CHECAGEM | K14: SharePoint / Office Script
A15: B20260825162659-1001 | B15: 46259.685 | C15: 46259 | D15: TERÇA-FEIRA | E15: 1001 | F15: Adriana Pereira dos Santos | G15: FIM | H15: ESTADUAL - OTEMPO | I15: CHECAGEM | K15: SharePoint / Office Script
A16: B20260825170543-1015 | B16: 46259.712 | C16: 46259 | D16: TERÇA-FEIRA | E16: 1015 | F16: Vitor Guilherme Miguel Rocha | G16: INÍCIO | H16: ADMINISTRATIVO | I16: ADMINISTRATIVO | K16: SharePoint / Office Script
A17: B20260825175354-1015 | B17: 46259.746 | C17: 46259 | D17: TERÇA-FEIRA | E17: 1015 | F17: Vitor Guilherme Miguel Rocha | G17: FIM | H17: ADMINISTRATIVO | I17: ADMINISTRATIVO | K17: SharePoint / Office Script
A18: B20260826075539-1011 | B18: 46260.33 | C18: 46260 | D18: QUARTA-FEIRA | E18: 1011 | F18: Nathalia Arruda | G18: INÍCIO | H18: ESTADUAL - OTEMPO | I18: ANÁLISE | J18: Preparação dos materias para campo | K18: SharePoint / Office Script
A19: B20260826080734-1003 | B19: 46260.339 | C19: 46260 | D19: QUARTA-FEIRA | E19: 1003 | F19: Amanda do Carmo Ribeiro | G19: INÍCIO | H19: OTEMPO | I19: ANÁLISE | K19: SharePoint / Office Script
A20: B20260826081141-1013 | B20: 46260.341 | C20: 46260 | D20: QUARTA-FEIRA | E20: 1013 | F20: Rafaela Maria Resende Lara | G20: INÍCIO | H20: BC - CONFIANÇA PIX | I20: ANÁLISE | K20: SharePoint / Office Script
A21: B20260826085132-1015 | B21: 46260.369 | C21: 46260 | D21: QUARTA-FEIRA | E21: 1015 | F21: Vitor Guilherme Miguel Rocha | G21: INÍCIO | H21: ADMINISTRATIVO | I21: ADMINISTRATIVO | K21: SharePoint / Office Script
A22: B20260826085335-1002 | B22: 46260.371 | C22: 46260 | D22: QUARTA-FEIRA | E22: 1002 | F22: Alex de Almeida Mariano | G22: INÍCIO | H22: CFI / ACCION | I22: ANÁLISE | K22: SharePoint / Office Script
A23: B20260826090744-1016 | B23: 46260.38 | C23: 46260 | D23: QUARTA-FEIRA | E23: 1016 | F23: Ana Luisa Nardin | G23: INÍCIO | H23: CFI / ACCION | I23: ANÁLISE | K23: SharePoint / Office Script
A24: B20260826093319-1001 | B24: 46260.398 | C24: 46260 | D24: QUARTA-FEIRA | E24: 1001 | F24: Adriana Pereira dos Santos | G24: INÍCIO | H24: TOOLKIT | I24: SUPERVISÃO | J24: ESTOU NA SUPERVISÃO DO SICOOB CREDICOM TAMÉM | K24: SharePoint / Office Script
A25: B20260826095033-1014 | B25: 46260.41 | C25: 46260 | D25: QUARTA-FEIRA | E25: 1014 | F25: Robert Filipe Orlando de Souza | G25: INÍCIO | H25: OTEMPO | I25: TRANSCRIÇÃO | K25: SharePoint / Office Script
A26: B20260826102453-1012 | B26: 46260.434 | C26: 46260 | D26: QUARTA-FEIRA | E26: 1012 | F26: Nelma Lucia dos S. B. Brandão | G26: FIM | H26: OTEMPO | I26: APLICAÇÃO / ENTREVISTA | J26: Finalizei o teste encaminhei as observações | K26: SharePoint / Office Script
A27: B20260826102513-1012 | B27: 46260.434 | C27: 46260 | D27: QUARTA-FEIRA | E27: 1012 | F27: Nelma Lucia dos S. B. Brandão | G27: FIM | H27: OTEMPO | I27: APLICAÇÃO / ENTREVISTA | J27: Finalizei o teste encaminhei as observações | K27: SharePoint / Office Script
A28: B20260826102558-1012 | B28: 46260.435 | C28: 46260 | D28: QUARTA-FEIRA | E28: 1012 | F28: Nelma Lucia dos S. B. Brandão | G28: FIM | H28: OTEMPO | I28: APLICAÇÃO / ENTREVISTA | J28: Finalizei o teste encaminhei as observações | K28: SharePoint / Office Script
A29: B20260826102955-1012 | B29: 46260.437 | C29: 46260 | D29: QUARTA-FEIRA | E29: 1012 | F29: Nelma Lucia dos S. B. Brandão | G29: FIM | H29: OTEMPO | I29: APLICAÇÃO / ENTREVISTA | J29: Finalizei o teste encaminhei as observações | K29: SharePoint / Office Script
A30: B20260826103220-1012 | B30: 46260.439 | C30: 46260 | D30: QUARTA-FEIRA | E30: 1012 | F30: Nelma Lucia dos S. B. Brandão | G30: INÍCIO | H30: SICOOB CREDICOM | I30: CHECAGEM | K30: SharePoint / Office Script
A31: B20260826115043-1013 | B31: 46260.494 | C31: 46260 | D31: QUARTA-FEIRA | E31: 1013 | F31: Rafaela Maria Resende Lara | G31: FIM | H31: BC - CONFIANÇA PIX | I31: ANÁLISE | K31: SharePoint / Office Script
A32: B20260826115321-1003 | B32: 46260.495 | C32: 46260 | D32: QUARTA-FEIRA | E32: 1003 | F32: Amanda do Carmo Ribeiro | G32: FIM | H32: OTEMPO | I32: ANÁLISE | K32: SharePoint / Office Script
A33: B20260826120410-1004 | B33: 46260.503 | C33: 46260 | D33: QUARTA-FEIRA | E33: 1004 | F33: Angela Bertoli | G33: INÍCIO | H33: SICOOB CREDICOM | I33: CODIFICAÇÃO | J33: Controle das entrevistas por link e pagamento da bonificação dos médicos | K33: SharePoint / Office Script
A34: B20260826120943-1011 | B34: 46260.507 | C34: 46260 | D34: QUARTA-FEIRA | E34: 1011 | F34: Nathalia Arruda | G34: FIM | H34: ESTADUAL - OTEMPO | I34: ANÁLISE | J34: ajustes de materiais | K34: SharePoint / Office Script
A35: B20260826123026-1016 | B35: 46260.521 | C35: 46260 | D35: QUARTA-FEIRA | E35: 1016 | F35: Ana Luisa Nardin | G35: FIM | H35: CFI / ACCION | I35: ANÁLISE | K35: SharePoint / Office Script
A36: B20260826123837-1012 | B36: 46260.527 | C36: 46260 | D36: QUARTA-FEIRA | E36: 1012 | F36: Nelma Lucia dos S. B. Brandão | G36: FIM | H36: SICOOB CREDICOM | I36: CHECAGEM | K36: SharePoint / Office Script
A37: B20260826123934-1014 | B37: 46260.527 | C37: 46260 | D37: QUARTA-FEIRA | E37: 1014 | F37: Robert Filipe Orlando de Souza | G37: FIM | H37: OTEMPO | I37: TRANSCRIÇÃO | K37: SharePoint / Office Script
A38: B20260826124010-1011 | B38: 46260.528 | C38: 46260 | D38: QUARTA-FEIRA | E38: 1011 | F38: Nathalia Arruda | G38: INÍCIO | H38: OTEMPO | I38: ANÁLISE | J38: revisão questionario | K38: SharePoint / Office Script
A39: B20260826124602-1003 | B39: 46260.532 | C39: 46260 | D39: QUARTA-FEIRA | E39: 1003 | F39: Amanda do Carmo Ribeiro | G39: INÍCIO | H39: OTEMPO | I39: ANÁLISE | K39: SharePoint / Office Script
A40: B20260826124635-1013 | B40: 46260.532 | C40: 46260 | D40: QUARTA-FEIRA | E40: 1013 | F40: Rafaela Maria Resende Lara | G40: INÍCIO | H40: OTEMPO | I40: ANÁLISE | K40: SharePoint / Office Script
A41: B20260826130346-1015 | B41: 46260.544 | C41: 46260 | D41: QUARTA-FEIRA | E41: 1015 | F41: Vitor Guilherme Miguel Rocha | G41: FIM | H41: ADMINISTRATIVO | I41: ADMINISTRATIVO | K41: SharePoint / Office Script
A42: B20260826132605-1016 | B42: 46260.56 | C42: 46260 | D42: QUARTA-FEIRA | E42: 1016 | F42: Ana Luisa Nardin | G42: INÍCIO | H42: CFI / ACCION | I42: ANÁLISE | K42: SharePoint / Office Script
...

Sheet Registros
A1: REGISTROS CONSOLIDADOS DE HORAS
A2: Cada INÍCIO cria uma linha; o FIM correspondente conclui a mesma linha e calcula horas e valor.
A4: Registro ID | B4: Data | C4: Dia da semana | D4: Tipo de dia | E4: ID | F4: Pessoa | G4: Projeto | H4: Atividade | I4: Início | J4: Fim | K4: Horas | L4: Observação | M4: Base | N4: Taxa aplicada | O4: Diária | P4: Valor | Q4: Status | R4: 1º do dia | S4: Mês
A6: R20260825152719-1001 | B6: 46259 | C6: TERÇA-FEIRA | D6: DIA ÚTIL | E6: 1001 | F6: Adriana Pereira dos Santos | G6: SICOOB CREDICOM | H6: SUPERVISÃO | I6: 0.64396991 | J6: 0.64594907 | K6: 0.0475 | L6: supervisão e checagem | M6: Hora | N6: 17 | O6: 0 | P6: 0.8075 | Q6: CONCLUÍDO | R6: 1 | S6: 2026-08
A7: R20260825161730-1015 | B7: 46259 | C7: TERÇA-FEIRA | D7: DIA ÚTIL | E7: 1015 | F7: Vitor Guilherme Miguel Rocha | G7: ADMINISTRATIVO | H7: ADMINISTRATIVO | I7: 0.67881944 | J7: 0.68112269 | K7: 0.055277778 | M7: Hora | N7: 21.5 | O7: 0 | P7: 1.1884722 | Q7: CONCLUÍDO | R7: 1 | S7: 2026-08
A8: R20260825162622-1001 | B8: 46259 | C8: TERÇA-FEIRA | D8: DIA ÚTIL | E8: 1001 | F8: Adriana Pereira dos Santos | G8: ESTADUAL - OTEMPO | H8: CHECAGEM | I8: 0.68497685 | J8: 0.68540509 | K8: 0.010277778 | M8: Hora | N8: 17 | O8: 0 | P8: 0.17472222 | Q8: CONCLUÍDO | R8: 0 | S8: 2026-08
A9: R20260825170543-1015 | B9: 46259 | C9: TERÇA-FEIRA | D9: DIA ÚTIL | E9: 1015 | F9: Vitor Guilherme Miguel Rocha | G9: ADMINISTRATIVO | H9: ADMINISTRATIVO | I9: 0.71230324 | J9: 0.74576389 | K9: 0.80305556 | M9: Hora | N9: 21.5 | O9: 0 | P9: 17.265694 | Q9: CONCLUÍDO | R9: 0 | S9: 2026-08
A10: R20260826075539-1011 | B10: 46260 | C10: QUARTA-FEIRA | D10: DIA ÚTIL | E10: 1011 | F10: Nathalia Arruda | G10: ESTADUAL - OTEMPO | H10: ANÁLISE | I10: 0.3303125 | J10: 0.50674769 | K10: 4.2344444 | L10: ajustes de materiais | M10: Hora | N10: 23.5 | O10: 0 | P10: 99.509444 | Q10: CONCLUÍDO | R10: 1 | S10: 2026-08
A11: R20260826080734-1003 | B11: 46260 | C11: QUARTA-FEIRA | D11: DIA ÚTIL | E11: 1003 | F11: Amanda do Carmo Ribeiro | G11: OTEMPO | H11: ANÁLISE | I11: 0.33858796 | J11: 0.49538194 | K11: 3.7630556 | M11: Hora | N11: 23.5 | O11: 0 | P11: 88.431806 | Q11: CONCLUÍDO | R11: 1 | S11: 2026-08
A12: R20260826081141-1013 | B12: 46260 | C12: QUARTA-FEIRA | D12: DIA ÚTIL | E12: 1013 | F12: Rafaela Maria Resende Lara | G12: BC - CONFIANÇA PIX | H12: ANÁLISE | I12: 0.34144676 | M12: Hora | N12: 23.5 | O12: 0 | Q12: EM ABERTO | S12: 2026-08
A13: R20260826085132-1015 | B13: 46260 | C13: QUARTA-FEIRA | D13: DIA ÚTIL | E13: 1015 | F13: Vitor Guilherme Miguel Rocha | G13: ADMINISTRATIVO | H13: ADMINISTRATIVO | I13: 0.36912037 | J13: 0.54428241 | K13: 4.2038889 | M13: Hora | N13: 21.5 | O13: 0 | P13: 90.383611 | Q13: CONCLUÍDO | R13: 1 | S13: 2026-08
A14: R20260826085335-1002 | B14: 46260 | C14: QUARTA-FEIRA | D14: DIA ÚTIL | E14: 1002 | F14: Alex de Almeida Mariano | G14: CFI / ACCION | H14: ANÁLISE | I14: 0.37054398 | J14: 0.74967593 | K14: 9.0991667 | M14: Hora | N14: 23.5 | O14: 0 | P14: 213.83042 | Q14: CONCLUÍDO | R14: 1 | S14: 2026-08
A15: R20260826090744-1016 | B15: 46260 | C15: QUARTA-FEIRA | D15: DIA ÚTIL | E15: 1016 | F15: Ana Luisa Nardin | G15: CFI / ACCION | H15: ANÁLISE | I15: 0.38037037 | J15: 0.52113426 | K15: 3.3783333 | M15: Hora | N15: 23.5 | O15: 0 | P15: 79.390833 | Q15: CONCLUÍDO | R15: 1 | S15: 2026-08
A16: R20260826093319-1001 | B16: 46260 | C16: QUARTA-FEIRA | D16: DIA ÚTIL | E16: 1001 | F16: Adriana Pereira dos Santos | G16: TOOLKIT | H16: SUPERVISÃO | I16: 0.39813657 | J16: 0.605 | K16: 4.9647222 | L16: SUPERVISAÕ SICOOB TAMBE´M | M16: Hora | N16: 17 | O16: 0 | P16: 84.400278 | Q16: CONCLUÍDO | R16: 1 | S16: 2026-08
A17: R20260826095033-1014 | B17: 46260 | C17: QUARTA-FEIRA | D17: DIA ÚTIL | E17: 1014 | F17: Robert Filipe Orlando de Souza | G17: OTEMPO | H17: TRANSCRIÇÃO | I17: 0.41010417 | J17: 0.52747685 | K17: 2.8169444 | M17: Hora | N17: 21.5 | O17: 0 | P17: 60.564306 | Q17: CONCLUÍDO | R17: 1 | S17: 2026-08
A18: R20260826103220-1012 | B18: 46260 | C18: QUARTA-FEIRA | D18: DIA ÚTIL | E18: 1012 | F18: Nelma Lucia dos S. B. Brandão | G18: SICOOB CREDICOM | H18: CHECAGEM | I18: 0.43912037 | J18: 0.52681713 | K18: 2.1047222 | M18: Diária | N18: 0 | O18: 222.72 | P18: 222.72 | Q18: CONCLUÍDO | R18: 1 | S18: 2026-08
A19: R20260826120410-1004 | B19: 46260 | C19: QUARTA-FEIRA | D19: DIA ÚTIL | E19: 1004 | F19: Angela Bertoli | G19: SICOOB CREDICOM | H19: CODIFICAÇÃO | I19: 0.50289352 | J19: 0.56880787 | K19: 1.5819444 | L19: Codificação e controle dos pix | M19: Hora | N19: 21.5 | O19: 0 | P19: 34.011806 | Q19: CONCLUÍDO | R19: 1 | S19: 2026-08
A20: R20260826124010-1011 | B20: 46260 | C20: QUARTA-FEIRA | D20: DIA ÚTIL | E20: 1011 | F20: Nathalia Arruda | G20: OTEMPO | H20: ANÁLISE | I20: 0.52789352 | J20: 0.7528588 | K20: 5.3991667 | L20: rteste e revisão de questionario | M20: Hora | N20: 23.5 | O20: 0 | P20: 126.88042 | Q20: CONCLUÍDO | R20: 0 | S20: 2026-08
A21: R20260826132605-1016 | B21: 46260 | C21: QUARTA-FEIRA | D21: DIA ÚTIL | E21: 1016 | F21: Ana Luisa Nardin | G21: CFI / ACCION | H21: ANÁLISE | I21: 0.55978009 | J21: 0.52527778 | K21: 23.171944 | M21: Hora | N21: 23.5 | O21: 0 | P21: 544.54069 | Q21: CONCLUÍDO | R21: 1 | S21: 2026-08
A22: R20260826134239-1012 | B22: 46260 | C22: QUARTA-FEIRA | D22: DIA ÚTIL | E22: 1012 | F22: Nelma Lucia dos S. B. Brandão | G22: TOOLKIT | H22: CHECAGEM | I22: 0.57128472 | J22: 0.75644676 | K22: 4.4438889 | M22: Diária | N22: 0 | O22: 222.72 | P22: 0 | Q22: CONCLUÍDO | R22: 0 | S22: 2026-08
A23: R20260826134356-1014 | B23: 46260 | C23: QUARTA-FEIRA | D23: DIA ÚTIL | E23: 1014 | F23: Robert Filipe Orlando de Souza | G23: OTEMPO | H23: TRANSCRIÇÃO | I23: 0.57217593 | J23: 0.7521412 | K23: 4.3191667 | M23: Hora | N23: 21.5 | O23: 0 | P23: 92.862083 | Q23: CONCLUÍDO | R23: 0 | S23: 2026-08
A24: R20260826140218-1015 | B24: 46260 | C24: QUARTA-FEIRA | D24: DIA ÚTIL | E24: 1015 | F24: Vitor Guilherme Miguel Rocha | G24: ADMINISTRATIVO | H24: ADMINISTRATIVO | I24: 0.58493056 | J24: 0.74349537 | K24: 3.8055556 | M24: Hora | N24: 21.5 | O24: 0 | P24: 81.819444 | Q24: CONCLUÍDO | R24: 0 | S24: 2026-08
A25: R20260826150208-1001 | B25: 46260 | C25: QUARTA-FEIRA | D25: DIA ÚTIL | E25: 1001 | F25: Adriana Pereira dos Santos | G25: TOOLKIT | H25: SUPERVISÃO | I25: 0.62648148 | J25: 0.78876157 | K25: 3.8947222 | L25: SICOOB SUPERVISÃO TAMBÉM | M25: Hora | N25: 17 | O25: 0 | P25: 66.210278 | Q25: CONCLUÍDO | R25: 0 | S25: 2026-08
A26: R20260826151516-1006 | B26: 46260 | C26: QUARTA-FEIRA | D26: DIA ÚTIL | E26: 1006 | F26: Eliane dos Santos Oliveira | G26: TOOLKIT | H26: CHECAGEM | I26: 0.63560185 | J26: 0.97969907 | K26: 8.2583333 | L26: checagem toolkit | M26: Hora | N26: 14 | O26: 0 | P26: 115.61667 | Q26: CONCLUÍDO | R26: 1 | S26: 2026-08
A27: R20260826233229-1006 | B27: 46260 | C27: QUARTA-FEIRA | D27: DIA ÚTIL | E27: 1006 | F27: Eliane dos Santos Oliveira | G27: TOOLKIT | H27: CHECAGEM | I27: 0.9808912 | J27: 0.81027778 | K27: 19.905278 | L27: checagem toolkit | M27: Hora | N27: 14 | O27: 0 | P27: 278.67389 | Q27: CONCLUÍDO | R27: 1 | S27: 2026-08
A28: R20260827080506-1003 | B28: 46261 | C28: QUINTA-FEIRA | D28: DIA ÚTIL | E28: 1003 | F28: Amanda do Carmo Ribeiro | G28: OTEMPO | H28: ANÁLISE | I28: 0.336875 | J28: 0.75015046 | K28: 9.9186111 | M28: Hora | N28: 23.5 | O28: 0 | P28: 233.08736 | Q28: CONCLUÍDO | R28: 1 | S28: 2026-08
A29: R20260827080943-1002 | B29: 46261 | C29: QUINTA-FEIRA | D29: DIA ÚTIL | E29: 1002 | F29: Alex de Almeida Mariano | G29: CFI / ACCION | H29: ANÁLISE | I29: 0.34008102 | J29: 0.75261574 | K29: 9.9008333 | M29: Hora | N29: 23.5 | O29: 0 | P29: 232.66958 | Q29: CONCLUÍDO | R29: 1 | S29: 2026-08
A30: R20260827083241-1001 | B30: 46261 | C30: QUINTA-FEIRA | D30: DIA ÚTIL | E30: 1001 | F30: Adriana Pereira dos Santos | G30: TOOLKIT | H30: SUPERVISÃO | I30: 0.35603009 | J30: 0.6678125 | K30: 7.4827778 | L30: supervisão sicoob credicom | M30: Hora | N30: 17 | O30: 0 | P30: 127.20722 | Q30: CONCLUÍDO | R30: 1 | S30: 2026-08
A31: R20260827085251-1015 | B31: 46261 | C31: QUINTA-FEIRA | D31: DIA ÚTIL | E31: 1015 | F31: Vitor Guilherme Miguel Rocha | G31: ADMINISTRATIVO | H31: ADMINISTRATIVO | I31: 0.37003472 | J31: 0.53855324 | K31: 4.0444444 | M31: Hora | N31: 21.5 | O31: 0 | P31: 86.955556 | Q31: CONCLUÍDO | R31: 1 | S31: 2026-08
A32: R20260827085347-1011 | B32: 46261 | C32: QUINTA-FEIRA | D32: DIA ÚTIL | E32: 1011 | F32: Nathalia Arruda | G32: ESTADUAL - OTEMPO | H32: ANÁLISE | I32: 0.37068287 | J32: 0.75436343 | K32: 177.20833 | M32: Hora | N32: 23.5 | O32: 0 | P32: 4164.3958 | Q32: CONCLUÍDO | R32: 1 | S32: 2026-08
A33: R20260827091115-1004 | B33: 46261 | C33: QUINTA-FEIRA | D33: DIA ÚTIL | E33: 1004 | F33: Angela Bertoli | G33: SICOOB CREDICOM | H33: CODIFICAÇÃO | I33: 0.3828125 | J33: 0.54849537 | K33: 3.9763889 | L33: controle dos links e pagamento dos médicos | M33: Hora | N33: 21.5 | O33: 0 | P33: 85.492361 | Q33: CONCLUÍDO | R33: 1 | S33: 2026-08
A34: R20260827094456-1012 | B34: 46261 | C34: QUINTA-FEIRA | D34: DIA ÚTIL | E34: 1012 | F34: Nelma Lucia dos S. B. Brandão | G34: SICOOB CREDICOM | H34: CHECAGEM | I34: 0.4062037 | J34: 0.47416667 | K34: 1.6311111 | M34: Diária | N34: 0 | O34: 222.72 | P34: 222.72 | Q34: CONCLUÍDO | R34: 1 | S34: 2026-08
A35: R20260827100504-1014 | B35: 46261 | C35: QUINTA-FEIRA | D35: DIA ÚTIL | E35: 1014 | F35: Robert Filipe Orlando de Souza | G35: OTEMPO | H35: TRANSCRIÇÃO | I35: 0.42018519 | J35: 0.53351852 | K35: 2.72 | M35: Hora | N35: 21.5 | O35: 0 | P35: 58.48 | Q35: CONCLUÍDO | R35: 1 | S35: 2026-08
A36: R20260827112349-1012 | B36: 46261 | C36: QUINTA-FEIRA | D36: DIA ÚTIL | E36: 1012 | F36: Nelma Lucia dos S. B. Brandão | G36: OTEMPO | H36: APOIO OPERACIONAL | I36: 0.47487269 | J36: 0.54290509 | K36: 1.6327778 | L36: Intervalo para almoço | M36: Diária | N36: 0 | O36: 222.72 | P36: 0 | Q36: CONCLUÍDO | R36: 0 | S36: 2026-08
A37: R20260827135002-1016 | B37: 46261 | C37: QUINTA-FEIRA | D37: DIA ÚTIL | E37: 1016 | F37: Ana Luisa Nardin | G37: CFI / ACCION | H37: ANÁLISE | I37: 0.57641204 | J37: 0.755 | K37: 4.2861111 | M37: Hora | N37: 23.5 | O37: 0 | P37: 100.72361 | Q37: CONCLUÍDO | R37: 1 | S37: 2026-08
A38: R20260827135430-1015 | B38: 46261 | C38: QUINTA-FEIRA | D38: DIA ÚTIL | E38: 1015 | F38: Vitor Guilherme Miguel Rocha | G38: ADMINISTRATIVO | H38: ADMINISTRATIVO | I38: 0.57951389 | J38: 0.74686343 | K38: 4.0163889 | M38: Hora | N38: 21.5 | O38: 0 | P38: 86.352361 | Q38: CONCLUÍDO | R38: 0 | S38: 2026-08
A39: R20260827135528-1014 | B39: 46261 | C39: QUINTA-FEIRA | D39: DIA ÚTIL | E39: 1014 | F39: Robert Filipe Orlando de Souza | G39: OTEMPO | H39: TRANSCRIÇÃO | I39: 0.58018519 | J39: 0.75818287 | K39: 4.2719444 | M39: Hora | N39: 21.5 | O39: 0 | P39: 91.846806 | Q39: CONCLUÍDO | R39: 0 | S39: 2026-08
A40: R20260827141731-1012 | B40: 46261 | C40: QUINTA-FEIRA | D40: DIA ÚTIL | E40: 1012 | F40: Nelma Lucia dos S. B. Brandão | G40: OTEMPO | H40: APOIO OPERACIONAL | I40: 0.59549769 | M40: Diária | N40: 0 | O40: 222.72 | Q40: EM ABERTO | S40: 2026-08
A41: R20260827150635-1004 | B41: 46261 | C41: QUINTA-FEIRA | D41: DIA ÚTIL | E41: 1004 | F41: Angela Bertoli | G41: SICOOB CREDICOM | H41: CODIFICAÇÃO | I41: 0.62957176 | J41: 0.84657407 | K41: 5.2080556 | L41: links e os pix | M41: Hora | N41: 21.5 | O41: 0 | P41: 111.97319 | Q41: CONCLUÍDO | R41: 0 | S41: 2026-08
A42: R20260827163244-1001 | B42: 46261 | C42: QUINTA-FEIRA | D42: DIA ÚTIL | E42: 1001 | F42: Adriana Pereira dos Santos | G42: TOOLKIT | H42: SUPERVISÃO | I42: 0.68939815 | J42: 0.75890046 | K42: 1.6680556 | L42: Supervisao toolikit | M42: Hora | N42: 17 | O42: 0 | P42: 28.356944 | Q42: CONCLUÍDO | R42: 0 | S42: 2026-08
...

Sheet Resumo Pagamentos
A1: RESUMO MENSAL DE PAGAMENTOS
A2: Selecione o mês no formato AAAA-MM. Valores vêm automaticamente dos registros concluídos.
A4: Mês de apuração | B4: 2026-08
A6: ID | B6: Pessoa | C6: Base | D6: Horas úteis | E6: Horas FDS | F6: Horas totais | G6: Dias trabalhados | H6: R$/h útil | I6: R$/h FDS | J6: R$/diária | K6: Valor calculado | L6: Ajustes | M6: TOTAL A PAGAR | N6: Pendências
A7: 1001 | B7: Adriana Pereira dos Santos | C7: Hora | D7: =SUMIFS(tblRegistros[Horas],tblRegistros[ID],A7,tblRegistros[Tipo de dia],"DIA ÚTIL",tblRegistros[Mês],$B$4,tblRegistros[Status],"CONCLUÍDO") -> 27.731111 | E7: =SUMIFS(tblRegistros[Horas],tblRegistros[ID],A7,tblRegistros[Tipo de dia],"FDS/FERIADO",tblRegistros[Mês],$B$4,tblRegistros[Status],"CONCLUÍDO") -> 42.495833 | F7: =D7+E7 -> 70.226944 | G7: =SUMIFS(tblRegistros[1º do dia],tblRegistros[ID],A7,tblRegistros[Mês],$B$4,tblRegistros[Status],"CONCLUÍDO") -> 7 | H7: =IFERROR(INDEX('Cadastro Pessoas'!$D$5:$D$104,MATCH(A7,'Cadastro Pessoas'!$A$5:$A$104,0)),0) -> 17 | I7: =IFERROR(INDEX('Cadastro Pessoas'!$E$5:$E$104,MATCH(A7,'Cadastro Pessoas'!$A$5:$A$104,0)),0) -> 20 | J7: =IFERROR(INDEX('Cadastro Pessoas'!$F$5:$F$104,MATCH(A7,'Cadastro Pessoas'!$A$5:$A$104,0)),0) -> 0 | K7: =SUMIFS(tblRegistros[Valor],tblRegistros[ID],A7,tblRegistros[Mês],$B$4,tblRegistros[Status],"CONCLUÍDO") -> 1321.3456 | L7: 0 | M7: =K7+L7 -> 1321.3456 | N7: =COUNTIFS(tblRegistros[ID],A7,tblRegistros[Mês],$B$4,tblRegistros[Status],"EM ABERTO") -> 0
A8: 1002 | B8: Alex de Almeida Mariano | C8: Hora | D8: =SUMIFS(tblRegistros[Horas],tblRegistros[ID],A8,tblRegistros[Tipo de dia],"DIA ÚTIL",tblRegistros[Mês],$B$4,tblRegistros[Status],"CONCLUÍDO") -> 37.779444 | E8: =SUMIFS(tblRegistros[Horas],tblRegistros[ID],A8,tblRegistros[Tipo de dia],"FDS/FERIADO",tblRegistros[Mês],$B$4,tblRegistros[Status],"CONCLUÍDO") -> 0 | F8: =D8+E8 -> 37.779444 | G8: =SUMIFS(tblRegistros[1º do dia],tblRegistros[ID],A8,tblRegistros[Mês],$B$4,tblRegistros[Status],"CONCLUÍDO") -> 4 | H8: =IFERROR(INDEX('Cadastro Pessoas'!$D$5:$D$104,MATCH(A8,'Cadastro Pessoas'!$A$5:$A$104,0)),0) -> 23.5 | I8: =IFERROR(INDEX('Cadastro Pessoas'!$E$5:$E$104,MATCH(A8,'Cadastro Pessoas'!$A$5:$A$104,0)),0) -> 23.5 | J8: =IFERROR(INDEX('Cadastro Pessoas'!$F$5:$F$104,MATCH(A8,'Cadastro Pessoas'!$A$5:$A$104,0)),0) -> 0 | K8: =SUMIFS(tblRegistros[Valor],tblRegistros[ID],A8,tblRegistros[Mês],$B$4,tblRegistros[Status],"CONCLUÍDO") -> 887.81694 | L8: 0 | M8: =K8+L8 -> 887.81694 | N8: =COUNTIFS(tblRegistros[ID],A8,tblRegistros[Mês],$B$4,tblRegistros[Status],"EM ABERTO") -> 0
A9: 1003 | B9: Amanda do Carmo Ribeiro | C9: Hora | D9: =SUMIFS(tblRegistros[Horas],tblRegistros[ID],A9,tblRegistros[Tipo de dia],"DIA ÚTIL",tblRegistros[Mês],$B$4,tblRegistros[Status],"CONCLUÍDO") -> 31.022222 | E9: =SUMIFS(tblRegistros[Horas],tblRegistros[ID],A9,tblRegistros[Tipo de dia],"FDS/FERIADO",tblRegistros[Mês],$B$4,tblRegistros[Status],"CONCLUÍDO") -> 0 | F9: =D9+E9 -> 31.022222 | G9: =SUMIFS(tblRegistros[1º do dia],tblRegistros[ID],A9,tblRegistros[Mês],$B$4,tblRegistros[Status],"CONCLUÍDO") -> 4 | H9: =IFERROR(INDEX('Cadastro Pessoas'!$D$5:$D$104,MATCH(A9,'Cadastro Pessoas'!$A$5:$A$104,0)),0) -> 23.5 | I9: =IFERROR(INDEX('Cadastro Pessoas'!$E$5:$E$104,MATCH(A9,'Cadastro Pessoas'!$A$5:$A$104,0)),0) -> 23.5 | J9: =IFERROR(INDEX('Cadastro Pessoas'!$F$5:$F$104,MATCH(A9,'Cadastro Pessoas'!$A$5:$A$104,0)),0) -> 0 | K9: =SUMIFS(tblRegistros[Valor],tblRegistros[ID],A9,tblRegistros[Mês],$B$4,tblRegistros[Status],"CONCLUÍDO") -> 729.02222 | L9: 0 | M9: =K9+L9 -> 729.02222 | N9: =COUNTIFS(tblRegistros[ID],A9,tblRegistros[Mês],$B$4,tblRegistros[Status],"EM ABERTO") -> 0
A10: 1004 | B10: Angela Bertoli | C10: Hora | D10: =SUMIFS(tblRegistros[Horas],tblRegistros[ID],A10,tblRegistros[Tipo de dia],"DIA ÚTIL",tblRegistros[Mês],$B$4,tblRegistros[Status],"CONCLUÍDO") -> 10.766389 | E10: =SUMIFS(tblRegistros[Horas],tblRegistros[ID],A10,tblRegistros[Tipo de dia],"FDS/FERIADO",tblRegistros[Mês],$B$4,tblRegistros[Status],"CONCLUÍDO") -> 5.1861111 | F10: =D10+E10 -> 15.9525 | G10: =SUMIFS(tblRegistros[1º do dia],tblRegistros[ID],A10,tblRegistros[Mês],$B$4,tblRegistros[Status],"CONCLUÍDO") -> 3 | H10: =IFERROR(INDEX('Cadastro Pessoas'!$D$5:$D$104,MATCH(A10,'Cadastro Pessoas'!$A$5:$A$104,0)),0) -> 21.5 | I10: =IFERROR(INDEX('Cadastro Pessoas'!$E$5:$E$104,MATCH(A10,'Cadastro Pessoas'!$A$5:$A$104,0)),0) -> 20 | J10: =IFERROR(INDEX('Cadastro Pessoas'!$F$5:$F$104,MATCH(A10,'Cadastro Pessoas'!$A$5:$A$104,0)),0) -> 0 | K10: =SUMIFS(tblRegistros[Valor],tblRegistros[ID],A10,tblRegistros[Mês],$B$4,tblRegistros[Status],"CONCLUÍDO") -> 335.19958 | L10: 0 | M10: =K10+L10 -> 335.19958 | N10: =COUNTIFS(tblRegistros[ID],A10,tblRegistros[Mês],$B$4,tblRegistros[Status],"EM ABERTO") -> 0
A11: 1005 | B11: Carolina Fantini Vidigal Diniz Dias | C11: Hora | D11: =SUMIFS(tblRegistros[Horas],tblRegistros[ID],A11,tblRegistros[Tipo de dia],"DIA ÚTIL",tblRegistros[Mês],$B$4,tblRegistros[Status],"CONCLUÍDO") -> 0 | E11: =SUMIFS(tblRegistros[Horas],tblRegistros[ID],A11,tblRegistros[Tipo de dia],"FDS/FERIADO",tblRegistros[Mês],$B$4,tblRegistros[Status],"CONCLUÍDO") -> 0 | F11: =D11+E11 -> 0 | G11: =SUMIFS(tblRegistros[1º do dia],tblRegistros[ID],A11,tblRegistros[Mês],$B$4,tblRegistros[Status],"CONCLUÍDO") -> 0 | H11: =IFERROR(INDEX('Cadastro Pessoas'!$D$5:$D$104,MATCH(A11,'Cadastro Pessoas'!$A$5:$A$104,0)),0) -> 13 | I11: =IFERROR(INDEX('Cadastro Pessoas'!$E$5:$E$104,MATCH(A11,'Cadastro Pessoas'!$A$5:$A$104,0)),0) -> 16.5 | J11: =IFERROR(INDEX('Cadastro Pessoas'!$F$5:$F$104,MATCH(A11,'Cadastro Pessoas'!$A$5:$A$104,0)),0) -> 0 | K11: =SUMIFS(tblRegistros[Valor],tblRegistros[ID],A11,tblRegistros[Mês],$B$4,tblRegistros[Status],"CONCLUÍDO") -> 0 | L11: 0 | M11: =K11+L11 -> 0 | N11: =COUNTIFS(tblRegistros[ID],A11,tblRegistros[Mês],$B$4,tblRegistros[Status],"EM ABERTO") -> 0
A12: 1006 | B12: Eliane dos Santos Oliveira | C12: Hora | D12: =SUMIFS(tblRegistros[Horas],tblRegistros[ID],A12,tblRegistros[Tipo de dia],"DIA ÚTIL",tblRegistros[Mês],$B$4,tblRegistros[Status],"CONCLUÍDO") -> 45.0325 | E12: =SUMIFS(tblRegistros[Horas],tblRegistros[ID],A12,tblRegistros[Tipo de dia],"FDS/FERIADO",tblRegistros[Mês],$B$4,tblRegistros[Status],"CONCLUÍDO") -> 15.579722 | F12: =D12+E12 -> 60.612222 | G12: =SUMIFS(tblRegistros[1º do dia],tblRegistros[ID],A12,tblRegistros[Mês],$B$4,tblRegistros[Status],"CONCLUÍDO") -> 6 | H12: =IFERROR(INDEX('Cadastro Pessoas'!$D$5:$D$104,MATCH(A12,'Cadastro Pessoas'!$A$5:$A$104,0)),0) -> 14 | I12: =IFERROR(INDEX('Cadastro Pessoas'!$E$5:$E$104,MATCH(A12,'Cadastro Pessoas'!$A$5:$A$104,0)),0) -> 17 | J12: =IFERROR(INDEX('Cadastro Pessoas'!$F$5:$F$104,MATCH(A12,'Cadastro Pessoas'!$A$5:$A$104,0)),0) -> 0 | K12: =SUMIFS(tblRegistros[Valor],tblRegistros[ID],A12,tblRegistros[Mês],$B$4,tblRegistros[Status],"CONCLUÍDO") -> 895.31028 | L12: 0 | M12: =K12+L12 -> 895.31028 | N12: =COUNTIFS(tblRegistros[ID],A12,tblRegistros[Mês],$B$4,tblRegistros[Status],"EM ABERTO") -> 0
A13: 1007 | B13: Fernanda Lopes | C13: Hora | D13: =SUMIFS(tblRegistros[Horas],tblRegistros[ID],A13,tblRegistros[Tipo de dia],"DIA ÚTIL",tblRegistros[Mês],$B$4,tblRegistros[Status],"CONCLUÍDO") -> 0 | E13: =SUMIFS(tblRegistros[Horas],tblRegistros[ID],A13,tblRegistros[Tipo de dia],"FDS/FERIADO",tblRegistros[Mês],$B$4,tblRegistros[Status],"CONCLUÍDO") -> 0 | F13: =D13+E13 -> 0 | G13: =SUMIFS(tblRegistros[1º do dia],tblRegistros[ID],A13,tblRegistros[Mês],$B$4,tblRegistros[Status],"CONCLUÍDO") -> 0 | H13: =IFERROR(INDEX('Cadastro Pessoas'!$D$5:$D$104,MATCH(A13,'Cadastro Pessoas'!$A$5:$A$104,0)),0) -> 23.5 | I13: =IFERROR(INDEX('Cadastro Pessoas'!$E$5:$E$104,MATCH(A13,'Cadastro Pessoas'!$A$5:$A$104,0)),0) -> 23.5 | J13: =IFERROR(INDEX('Cadastro Pessoas'!$F$5:$F$104,MATCH(A13,'Cadastro Pessoas'!$A$5:$A$104,0)),0) -> 0 | K13: =SUMIFS(tblRegistros[Valor],tblRegistros[ID],A13,tblRegistros[Mês],$B$4,tblRegistros[Status],"CONCLUÍDO") -> 0 | L13: 0 | M13: =K13+L13 -> 0 | N13: =COUNTIFS(tblRegistros[ID],A13,tblRegistros[Mês],$B$4,tblRegistros[Status],"EM ABERTO") -> 0
A14: 1008 | B14: Flávia Reis | C14: Hora | D14: =SUMIFS(tblRegistros[Horas],tblRegistros[ID],A14,tblRegistros[Tipo de dia],"DIA ÚTIL",tblRegistros[Mês],$B$4,tblRegistros[Status],"CONCLUÍDO") -> 0 | E14: =SUMIFS(tblRegistros[Horas],tblRegistros[ID],A14,tblRegistros[Tipo de dia],"FDS/FERIADO",tblRegistros[Mês],$B$4,tblRegistros[Status],"CONCLUÍDO") -> 0 | F14: =D14+E14 -> 0 | G14: =SUMIFS(tblRegistros[1º do dia],tblRegistros[ID],A14,tblRegistros[Mês],$B$4,tblRegistros[Status],"CONCLUÍDO") -> 0 | H14: =IFERROR(INDEX('Cadastro Pessoas'!$D$5:$D$104,MATCH(A14,'Cadastro Pessoas'!$A$5:$A$104,0)),0) -> 14 | I14: =IFERROR(INDEX('Cadastro Pessoas'!$E$5:$E$104,MATCH(A14,'Cadastro Pessoas'!$A$5:$A$104,0)),0) -> 17 | J14: =IFERROR(INDEX('Cadastro Pessoas'!$F$5:$F$104,MATCH(A14,'Cadastro Pessoas'!$A$5:$A$104,0)),0) -> 0 | K14: =SUMIFS(tblRegistros[Valor],tblRegistros[ID],A14,tblRegistros[Mês],$B$4,tblRegistros[Status],"CONCLUÍDO") -> 0 | L14: 0 | M14: =K14+L14 -> 0 | N14: =COUNTIFS(tblRegistros[ID],A14,tblRegistros[Mês],$B$4,tblRegistros[Status],"EM ABERTO") -> 0
A15: 1009 | B15: Junia Maria Santos | C15: Hora | D15: =SUMIFS(tblRegistros[Horas],tblRegistros[ID],A15,tblRegistros[Tipo de dia],"DIA ÚTIL",tblRegistros[Mês],$B$4,tblRegistros[Status],"CONCLUÍDO") -> 0 | E15: =SUMIFS(tblRegistros[Horas],tblRegistros[ID],A15,tblRegistros[Tipo de dia],"FDS/FERIADO",tblRegistros[Mês],$B$4,tblRegistros[Status],"CONCLUÍDO") -> 0 | F15: =D15+E15 -> 0 | G15: =SUMIFS(tblRegistros[1º do dia],tblRegistros[ID],A15,tblRegistros[Mês],$B$4,tblRegistros[Status],"CONCLUÍDO") -> 0 | H15: =IFERROR(INDEX('Cadastro Pessoas'!$D$5:$D$104,MATCH(A15,'Cadastro Pessoas'!$A$5:$A$104,0)),0) -> 14 | I15: =IFERROR(INDEX('Cadastro Pessoas'!$E$5:$E$104,MATCH(A15,'Cadastro Pessoas'!$A$5:$A$104,0)),0) -> 17 | J15: =IFERROR(INDEX('Cadastro Pessoas'!$F$5:$F$104,MATCH(A15,'Cadastro Pessoas'!$A$5:$A$104,0)),0) -> 0 | K15: =SUMIFS(tblRegistros[Valor],tblRegistros[ID],A15,tblRegistros[Mês],$B$4,tblRegistros[Status],"CONCLUÍDO") -> 0 | L15: 0 | M15: =K15+L15 -> 0 | N15: =COUNTIFS(tblRegistros[ID],A15,tblRegistros[Mês],$B$4,tblRegistros[Status],"EM ABERTO") -> 0
A16: 1010 | B16: Nataly Tayê | C16: Hora | D16: =SUMIFS(tblRegistros[Horas],tblRegistros[ID],A16,tblRegistros[Tipo de dia],"DIA ÚTIL",tblRegistros[Mês],$B$4,tblRegistros[Status],"CONCLUÍDO") -> 0 | E16: =SUMIFS(tblRegistros[Horas],tblRegistros[ID],A16,tblRegistros[Tipo de dia],"FDS/FERIADO",tblRegistros[Mês],$B$4,tblRegistros[Status],"CONCLUÍDO") -> 0 | F16: =D16+E16 -> 0 | G16: =SUMIFS(tblRegistros[1º do dia],tblRegistros[ID],A16,tblRegistros[Mês],$B$4,tblRegistros[Status],"CONCLUÍDO") -> 0 | H16: =IFERROR(INDEX('Cadastro Pessoas'!$D$5:$D$104,MATCH(A16,'Cadastro Pessoas'!$A$5:$A$104,0)),0) -> 14 | I16: =IFERROR(INDEX('Cadastro Pessoas'!$E$5:$E$104,MATCH(A16,'Cadastro Pessoas'!$A$5:$A$104,0)),0) -> 17 | J16: =IFERROR(INDEX('Cadastro Pessoas'!$F$5:$F$104,MATCH(A16,'Cadastro Pessoas'!$A$5:$A$104,0)),0) -> 0 | K16: =SUMIFS(tblRegistros[Valor],tblRegistros[ID],A16,tblRegistros[Mês],$B$4,tblRegistros[Status],"CONCLUÍDO") -> 0 | L16: 0 | M16: =K16+L16 -> 0 | N16: =COUNTIFS(tblRegistros[ID],A16,tblRegistros[Mês],$B$4,tblRegistros[Status],"EM ABERTO") -> 0
A17: 1011 | B17: Nathalia Arruda | C17: Hora | D17: =SUMIFS(tblRegistros[Horas],tblRegistros[ID],A17,tblRegistros[Tipo de dia],"DIA ÚTIL",tblRegistros[Mês],$B$4,tblRegistros[Status],"CONCLUÍDO") -> 186.84194 | E17: =SUMIFS(tblRegistros[Horas],tblRegistros[ID],A17,tblRegistros[Tipo de dia],"FDS/FERIADO",tblRegistros[Mês],$B$4,tblRegistros[Status],"CONCLUÍDO") -> 0 | F17: =D17+E17 -> 186.84194 | G17: =SUMIFS(tblRegistros[1º do dia],tblRegistros[ID],A17,tblRegistros[Mês],$B$4,tblRegistros[Status],"CONCLUÍDO") -> 2 | H17: =IFERROR(INDEX('Cadastro Pessoas'!$D$5:$D$104,MATCH(A17,'Cadastro Pessoas'!$A$5:$A$104,0)),0) -> 23.5 | I17: =IFERROR(INDEX('Cadastro Pessoas'!$E$5:$E$104,MATCH(A17,'Cadastro Pessoas'!$A$5:$A$104,0)),0) -> 23.5 | J17: =IFERROR(INDEX('Cadastro Pessoas'!$F$5:$F$104,MATCH(A17,'Cadastro Pessoas'!$A$5:$A$104,0)),0) -> 0 | K17: =SUMIFS(tblRegistros[Valor],tblRegistros[ID],A17,tblRegistros[Mês],$B$4,tblRegistros[Status],"CONCLUÍDO") -> 4390.7857 | L17: 0 | M17: =K17+L17 -> 4390.7857 | N17: =COUNTIFS(tblRegistros[ID],A17,tblRegistros[Mês],$B$4,tblRegistros[Status],"EM ABERTO") -> 0
A18: 1012 | B18: Nelma Lucia dos S. B. Brandão | C18: Diária | D18: =SUMIFS(tblRegistros[Horas],tblRegistros[ID],A18,tblRegistros[Tipo de dia],"DIA ÚTIL",tblRegistros[Mês],$B$4,tblRegistros[Status],"CONCLUÍDO") -> 9.8125 | E18: =SUMIFS(tblRegistros[Horas],tblRegistros[ID],A18,tblRegistros[Tipo de dia],"FDS/FERIADO",tblRegistros[Mês],$B$4,tblRegistros[Status],"CONCLUÍDO") -> 0 | F18: =D18+E18 -> 9.8125 | G18: =SUMIFS(tblRegistros[1º do dia],tblRegistros[ID],A18,tblRegistros[Mês],$B$4,tblRegistros[Status],"CONCLUÍDO") -> 2 | H18: =IFERROR(INDEX('Cadastro Pessoas'!$D$5:$D$104,MATCH(A18,'Cadastro Pessoas'!$A$5:$A$104,0)),0) -> 0 | I18: =IFERROR(INDEX('Cadastro Pessoas'!$E$5:$E$104,MATCH(A18,'Cadastro Pessoas'!$A$5:$A$104,0)),0) -> 0 | J18: =IFERROR(INDEX('Cadastro Pessoas'!$F$5:$F$104,MATCH(A18,'Cadastro Pessoas'!$A$5:$A$104,0)),0) -> 222.72 | K18: =SUMIFS(tblRegistros[Valor],tblRegistros[ID],A18,tblRegistros[Mês],$B$4,tblRegistros[Status],"CONCLUÍDO") -> 445.44 | L18: 0 | M18: =K18+L18 -> 445.44 | N18: =COUNTIFS(tblRegistros[ID],A18,tblRegistros[Mês],$B$4,tblRegistros[Status],"EM ABERTO") -> 1
... A20: 1014 | B20: Robert Filipe Orlando de Souza | C20: Hora | D20: =SUMIFS(tblRegistros[Horas],tblRegistros[ID],A20,tblRegistros[Tipo de dia],"DIA ÚTIL",tblRegistros[Mês],$B$4,tblRegistros[Status],"CONCLUÍDO") -> 27.990833 | E20: =SUMIFS(tblRegistros[Horas],tblRegistros[ID],A20,tblRegistros[Tipo de dia],"FDS/FERIADO",tblRegistros[Mês],$B$4,tblRegistros[Status],"CONCLUÍDO") -> 0 | F20: =D20+E20 -> 27.990833 | G20: =SUMIFS(tblRegistros[1º do dia],tblRegistros[ID],A20,tblRegistros[Mês],$B$4,tblRegistros[Status],"CONCLUÍDO") -> 4 | H20: =IFERROR(INDEX('Cadastro Pessoas'!$D$5:$D$104,MATCH(A20,'Cadastro Pessoas'!$A$5:$A$104,0)),0) -> 21.5 | I20: =IFERROR(INDEX('Cadastro Pessoas'!$E$5:$E$104,MATCH(A20,'Cadastro Pessoas'!$A$5:$A$104,0)),0) -> 21.5 | J20: =IFERROR(INDEX('Cadastro Pessoas'!$F$5:$F$104,MATCH(A20,'Cadastro Pessoas'!$A$5:$A$104,0)),0) -> 0 | K20: =SUMIFS(tblRegistros[Valor],tblRegistros[ID],A20,tblRegistros[Mês],$B$4,tblRegistros[Status],"CONCLUÍDO") -> 601.80292 | L20: 0 | M20: =K20+L20 -> 601.80292 | N20: =COUNTIFS(tblRegistros[ID],A20,tblRegistros[Mês],$B$4,tblRegistros[Status],"EM ABERTO") -> 0
A21: 1015 | B21: Vitor Guilherme Miguel Rocha | C21: Hora | D21: =SUMIFS(Registros!$K$5:$K$30237,Registros!$E$5:$E$30237,A21,Registros!$D$5:$D$30237,"DIA ÚTIL",Registros!$S$5:$S$30237,$B$4,Registros!$Q$5:$Q$30237,"CONCLUÍDO") -> 32.846667 | E21: =SUMIFS(Registros!$K$5:$K$30237,Registros!$E$5:$E$30237,A21,Registros!$D$5:$D$30237,"FDS/FERIADO",Registros!$S$5:$S$30237,$B$4,Registros!$Q$5:$Q$30237,"CONCLUÍDO") -> 0 | F21: =D21+E21 -> 32.846667 | G21: =SUMIFS(Registros!$R$5:$R$30237,Registros!$E$5:$E$30237,A21,Registros!$S$5:$S$30237,$B$4,Registros!$Q$5:$Q$30237,"CONCLUÍDO") -> 5 | H21: 21.5 | I21: 21.5 | J21: 0 | K21: =SUMIFS(Registros!$P$5:$P$30237,Registros!$E$5:$E$30237,A21,Registros!$S$5:$S$30237,$B$4,Registros!$Q$5:$Q$30237,"CONCLUÍDO") -> 706.20333 | L21: 0 | M21: =K21+L21 -> 706.20333 | N21: =COUNTIFS(Registros!$E$5:$E$30237,A21,Registros!$S$5:$S$30237,$B$4,Registros!$Q$5:$Q$30237,"EM ABERTO") -> 0
A22: 1016 | B22: Ana Luisa Nardin | C22: Hora | D22: =SUMIFS(Registros!$K$5:$K$30229,Registros!$E$5:$E$30229,A22,Registros!$D$5:$D$30229,"DIA ÚTIL",Registros!$S$5:$S$30229,$B$4,Registros!$Q$5:$Q$30229,"CONCLUÍDO") -> 110.63556 | E22: =SUMIFS(Registros!$K$5:$K$30229,Registros!$E$5:$E$30229,A22,Registros!$D$5:$D$30229,"FDS/FERIADO",Registros!$S$5:$S$30229,$B$4,Registros!$Q$5:$Q$30229,"CONCLUÍDO") -> 0 | F22: =D22+E22 -> 110.63556 | G22: =SUMIFS(Registros!$R$5:$R$30229,Registros!$E$5:$E$30229,A22,Registros!$S$5:$S$30229,$B$4,Registros!$Q$5:$Q$30229,"CONCLUÍDO") -> 4 | H22: 23.5 | I22: 23.5 | J22: 0 | K22: =SUMIFS(Registros!$P$5:$P$30229,Registros!$E$5:$E$30229,A22,Registros!$S$5:$S$30229,$B$4,Registros!$Q$5:$Q$30229,"CONCLUÍDO") -> 2599.9356 | L22: 0 | M22: =K22+L22 -> 2599.9356 | N22: =COUNTIFS(Registros!$E$5:$E$30229,A22,Registros!$S$5:$S$30229,$B$4,Registros!$Q$5:$Q$30229,"EM ABERTO") -> 0
A23: 1017 | B23: Renato Inácio da Silva | C23: Hora | D23: =SUMIFS(Registros!$K$5:$K$30065,Registros!$E$5:$E$30065,A23,Registros!$D$5:$D$30065,"DIA ÚTIL",Registros!$S$5:$S$30065,$B$4,Registros!$Q$5:$Q$30065,"CONCLUÍDO") -> 0 | E23: =SUMIFS(Registros!$K$5:$K$30065,Registros!$E$5:$E$30065,A23,Registros!$D$5:$D$30065,"FDS/FERIADO",Registros!$S$5:$S$30065,$B$4,Registros!$Q$5:$Q$30065,"CONCLUÍDO") -> 0 | F23: =D23+E23 -> 0 | G23: =SUMIFS(Registros!$R$5:$R$30065,Registros!$E$5:$E$30065,A23,Registros!$S$5:$S$30065,$B$4,Registros!$Q$5:$Q$30065,"CONCLUÍDO") -> 0 | H23: 14 | I23: 17 | J23: 0 | K23: =SUMIFS(Registros!$P$5:$P$30065,Registros!$E$5:$E$30065,A23,Registros!$S$5:$S$30065,$B$4,Registros!$Q$5:$Q$30065,"CONCLUÍDO") -> 0 | L23: 0 | M23: =K23+L23 -> 0 | N23: =COUNTIFS(Registros!$E$5:$E$30065,A23,Registros!$S$5:$S$30065,$B$4,Registros!$Q$5:$Q$30065,"EM ABERTO") -> 0
A107: TOTAL GERAL | M107: =SUM(M7:M106) -> 12912.862

Sheet Custo por Projeto
A1: CUSTO MENSAL POR PROJETO
A2: Horas, pessoas e custos consolidados a partir dos nomes padronizados.
A4: Mês de apuração | B4: 2026-08
A6: Código | B6: Projeto | C6: Horas úteis | D6: Horas FDS | E6: Horas totais | F6: Registros | G6: Pessoas | H6: Custo total
A7: PRJ-001 | B7: BANCO CENTRAL | C7: =SUMIFS(tblRegistros[Horas],tblRegistros[Projeto],B7,tblRegistros[Tipo de dia],"DIA ÚTIL",tblRegistros[Mês],$B$4,tblRegistros[Status],"CONCLUÍDO") -> 0 | D7: =SUMIFS(tblRegistros[Horas],tblRegistros[Projeto],B7,tblRegistros[Tipo de dia],"FDS/FERIADO",tblRegistros[Mês],$B$4,tblRegistros[Status],"CONCLUÍDO") -> 0 | E7: =C7+D7 -> 0 | F7: =COUNTIFS(tblRegistros[Projeto],B7,tblRegistros[Mês],$B$4,tblRegistros[Status],"CONCLUÍDO") -> 0 | G7: =IF(F7=0,0,IFERROR(ROWS(_xlfn.UNIQUE(_xlfn._xlws.FILTER(tblRegistros[ID],(tblRegistros[Projeto]=B7)*(tblRegistros[Mês]=$B$4)*(tblRegistros[Status]="CONCLUÍDO")))),0)) -> 0 | H7: =SUMIFS(tblRegistros[Valor],tblRegistros[Projeto],B7,tblRegistros[Mês],$B$4,tblRegistros[Status],"CONCLUÍDO") -> 0
A8: PRJ-002 | B8: CFI / ACCION | C8: =SUMIFS(tblRegistros[Horas],tblRegistros[Projeto],B8,tblRegistros[Tipo de dia],"DIA ÚTIL",tblRegistros[Mês],$B$4,tblRegistros[Status],"CONCLUÍDO") -> 148.415 | D8: =SUMIFS(tblRegistros[Horas],tblRegistros[Projeto],B8,tblRegistros[Tipo de dia],"FDS/FERIADO",tblRegistros[Mês],$B$4,tblRegistros[Status],"CONCLUÍDO") -> 0 | E8: =C8+D8 -> 148.415 | F8: =COUNTIFS(tblRegistros[Projeto],B8,tblRegistros[Mês],$B$4,tblRegistros[Status],"CONCLUÍDO") -> 8 | G8: =IF(F8=0,0,IFERROR(ROWS(_xlfn.UNIQUE(_xlfn._xlws.FILTER(tblRegistros[ID],(tblRegistros[Projeto]=B8)*(tblRegistros[Mês]=$B$4)*(tblRegistros[Status]="CONCLUÍDO")))),0)) -> 2 | H8: =SUMIFS(tblRegistros[Valor],tblRegistros[Projeto],B8,tblRegistros[Mês],$B$4,tblRegistros[Status],"CONCLUÍDO") -> 3487.7525
A9: PRJ-003 | B9: SICOOB CREDICOM | C9: =SUMIFS(tblRegistros[Horas],tblRegistros[Projeto],B9,tblRegistros[Tipo de dia],"DIA ÚTIL",tblRegistros[Mês],$B$4,tblRegistros[Status],"CONCLUÍDO") -> 25.981944 | D9: =SUMIFS(tblRegistros[Horas],tblRegistros[Projeto],B9,tblRegistros[Tipo de dia],"FDS/FERIADO",tblRegistros[Mês],$B$4,tblRegistros[Status],"CONCLUÍDO") -> 44.792778 | E9: =C9+D9 -> 70.774722 | F9: =COUNTIFS(tblRegistros[Projeto],B9,tblRegistros[Mês],$B$4,tblRegistros[Status],"CONCLUÍDO") -> 15 | G9: =IF(F9=0,0,IFERROR(ROWS(_xlfn.UNIQUE(_xlfn._xlws.FILTER(tblRegistros[ID],(tblRegistros[Projeto]=B9)*(tblRegistros[Mês]=$B$4)*(tblRegistros[Status]="CONCLUÍDO")))),0)) -> 4 | H9: =SUMIFS(tblRegistros[Valor],tblRegistros[Projeto],B9,tblRegistros[Mês],$B$4,tblRegistros[Status],"CONCLUÍDO") -> 1819.3732
A10: PRJ-004 | B10: O TEMPO | C10: =SUMIFS(tblRegistros[Horas],tblRegistros[Projeto],B10,tblRegistros[Tipo de dia],"DIA ÚTIL",tblRegistros[Mês],$B$4,tblRegistros[Status],"CONCLUÍDO") -> 0 | D10: =SUMIFS(tblRegistros[Horas],tblRegistros[Projeto],B10,tblRegistros[Tipo de dia],"FDS/FERIADO",tblRegistros[Mês],$B$4,tblRegistros[Status],"CONCLUÍDO") -> 0 | E10: =C10+D10 -> 0 | F10: =COUNTIFS(tblRegistros[Projeto],B10,tblRegistros[Mês],$B$4,tblRegistros[Status],"CONCLUÍDO") -> 0 | G10: =IF(F10=0,0,IFERROR(ROWS(_xlfn.UNIQUE(_xlfn._xlws.FILTER(tblRegistros[ID],(tblRegistros[Projeto]=B10)*(tblRegistros[Mês]=$B$4)*(tblRegistros[Status]="CONCLUÍDO")))),0)) -> 0 | H10: =SUMIFS(tblRegistros[Valor],tblRegistros[Projeto],B10,tblRegistros[Mês],$B$4,tblRegistros[Status],"CONCLUÍDO") -> 0
A11: PRJ-005 | B11: ELEITORAL MG 2026 | C11: =SUMIFS(tblRegistros[Horas],tblRegistros[Projeto],B11,tblRegistros[Tipo de dia],"DIA ÚTIL",tblRegistros[Mês],$B$4,tblRegistros[Status],"CONCLUÍDO") -> 0 | D11: =SUMIFS(tblRegistros[Horas],tblRegistros[Projeto],B11,tblRegistros[Tipo de dia],"FDS/FERIADO",tblRegistros[Mês],$B$4,tblRegistros[Status],"CONCLUÍDO") -> 0 | E11: =C11+D11 -> 0 | F11: =COUNTIFS(tblRegistros[Projeto],B11,tblRegistros[Mês],$B$4,tblRegistros[Status],"CONCLUÍDO") -> 0 | G11: =IF(F11=0,0,IFERROR(ROWS(_xlfn.UNIQUE(_xlfn._xlws.FILTER(tblRegistros[ID],(tblRegistros[Projeto]=B11)*(tblRegistros[Mês]=$B$4)*(tblRegistros[Status]="CONCLUÍDO")))),0)) -> 0 | H11: =SUMIFS(tblRegistros[Valor],tblRegistros[Projeto],B11,tblRegistros[Mês],$B$4,tblRegistros[Status],"CONCLUÍDO") -> 0
A12: PRJ-006 | B12: CNI | C12: =SUMIFS(tblRegistros[Horas],tblRegistros[Projeto],B12,tblRegistros[Tipo de dia],"DIA ÚTIL",tblRegistros[Mês],$B$4,tblRegistros[Status],"CONCLUÍDO") -> 0 | D12: =SUMIFS(tblRegistros[Horas],tblRegistros[Projeto],B12,tblRegistros[Tipo de dia],"FDS/FERIADO",tblRegistros[Mês],$B$4,tblRegistros[Status],"CONCLUÍDO") -> 0 | E12: =C12+D12 -> 0 | F12: =COUNTIFS(tblRegistros[Projeto],B12,tblRegistros[Mês],$B$4,tblRegistros[Status],"CONCLUÍDO") -> 0 | G12: =IF(F12=0,0,IFERROR(ROWS(_xlfn.UNIQUE(_xlfn._xlws.FILTER(tblRegistros[ID],(tblRegistros[Projeto]=B12)*(tblRegistros[Mês]=$B$4)*(tblRegistros[Status]="CONCLUÍDO")))),0)) -> 0 | H12: =SUMIFS(tblRegistros[Valor],tblRegistros[Projeto],B12,tblRegistros[Mês],$B$4,tblRegistros[Status],"CONCLUÍDO") -> 0
A13: PRJ-007 | B13: TOOLKIT | C13: =SUMIFS(tblRegistros[Horas],tblRegistros[Projeto],B13,tblRegistros[Tipo de dia],"DIA ÚTIL",tblRegistros[Mês],$B$4,tblRegistros[Status],"CONCLUÍDO") -> 64.531944 | D13: =SUMIFS(tblRegistros[Horas],tblRegistros[Projeto],B13,tblRegistros[Tipo de dia],"FDS/FERIADO",tblRegistros[Mês],$B$4,tblRegistros[Status],"CONCLUÍDO") -> 2.8891667 | E13: =C13+D13 -> 67.421111 | F13: =COUNTIFS(tblRegistros[Projeto],B13,tblRegistros[Mês],$B$4,tblRegistros[Status],"CONCLUÍDO") -> 13 | G13: =IF(F13=0,0,IFERROR(ROWS(_xlfn.UNIQUE(_xlfn._xlws.FILTER(tblRegistros[ID],(tblRegistros[Projeto]=B13)*(tblRegistros[Mês]=$B$4)*(tblRegistros[Status]="CONCLUÍDO")))),0)) -> 5 | H13: =SUMIFS(tblRegistros[Valor],tblRegistros[Projeto],B13,tblRegistros[Mês],$B$4,tblRegistros[Status],"CONCLUÍDO") -> 1000.2653
A14: PRJ-008 | B14: BH SHOPPING | C14: =SUMIFS(tblRegistros[Horas],tblRegistros[Projeto],B14,tblRegistros[Tipo de dia],"DIA ÚTIL",tblRegistros[Mês],$B$4,tblRegistros[Status],"CONCLUÍDO") -> 0 | D14: =SUMIFS(tblRegistros[Horas],tblRegistros[Projeto],B14,tblRegistros[Tipo de dia],"FDS/FERIADO",tblRegistros[Mês],$B$4,tblRegistros[Status],"CONCLUÍDO") -> 0 | E14: =C14+D14 -> 0 | F14: =COUNTIFS(tblRegistros[Projeto],B14,tblRegistros[Mês],$B$4,tblRegistros[Status],"CONCLUÍDO") -> 0 | G14: =IF(F14=0,0,IFERROR(ROWS(_xlfn.UNIQUE(_xlfn._xlws.FILTER(tblRegistros[ID],(tblRegistros[Projeto]=B14)*(tblRegistros[Mês]=$B$4)*(tblRegistros[Status]="CONCLUÍDO")))),0)) -> 0 | H14: =SUMIFS(tblRegistros[Valor],tblRegistros[Projeto],B14,tblRegistros[Mês],$B$4,tblRegistros[Status],"CONCLUÍDO") -> 0
A15: PRJ-009 | B15: ADMINISTRATIVO | C15: =SUMIFS(tblRegistros[Horas],tblRegistros[Projeto],B15,tblRegistros[Tipo de dia],"DIA ÚTIL",tblRegistros[Mês],$B$4,tblRegistros[Status],"CONCLUÍDO") -> 32.846667 | D15: =SUMIFS(tblRegistros[Horas],tblRegistros[Projeto],B15,tblRegistros[Tipo de dia],"FDS/FERIADO",tblRegistros[Mês],$B$4,tblRegistros[Status],"CONCLUÍDO") -> 0 | E15: =C15+D15 -> 32.846667 | F15: =COUNTIFS(tblRegistros[Projeto],B15,tblRegistros[Mês],$B$4,tblRegistros[Status],"CONCLUÍDO") -> 10 | G15: =IF(F15=0,0,IFERROR(ROWS(_xlfn.UNIQUE(_xlfn._xlws.FILTER(tblRegistros[ID],(tblRegistros[Projeto]=B15)*(tblRegistros[Mês]=$B$4)*(tblRegistros[Status]="CONCLUÍDO")))),0)) -> 1 | H15: =SUMIFS(tblRegistros[Valor],tblRegistros[Projeto],B15,tblRegistros[Mês],$B$4,tblRegistros[Status],"CONCLUÍDO") -> 706.20333
A16: PRJ-010 | B16: OUTROS | C16: =SUMIFS(tblRegistros[Horas],tblRegistros[Projeto],B16,tblRegistros[Tipo de dia],"DIA ÚTIL",tblRegistros[Mês],$B$4,tblRegistros[Status],"CONCLUÍDO") -> 0 | D16: =SUMIFS(tblRegistros[Horas],tblRegistros[Projeto],B16,tblRegistros[Tipo de dia],"FDS/FERIADO",tblRegistros[Mês],$B$4,tblRegistros[Status],"CONCLUÍDO") -> 0 | E16: =C16+D16 -> 0 | F16: =COUNTIFS(tblRegistros[Projeto],B16,tblRegistros[Mês],$B$4,tblRegistros[Status],"CONCLUÍDO") -> 0 | G16: =IF(F16=0,0,IFERROR(ROWS(_xlfn.UNIQUE(_xlfn._xlws.FILTER(tblRegistros[ID],(tblRegistros[Projeto]=B16)*(tblRegistros[Mês]=$B$4)*(tblRegistros[Status]="CONCLUÍDO")))),0)) -> 0 | H16: =SUMIFS(tblRegistros[Valor],tblRegistros[Projeto],B16,tblRegistros[Mês],$B$4,tblRegistros[Status],"CONCLUÍDO") -> 0
A17: PRJ-005 | B17: ESTADUAL - OTEMPO | C17: =SUMIFS(Registros!$K$5:$K$30236,Registros!$G$5:$G$30236,B17,Registros!$D$5:$D$30236,"DIA ÚTIL",Registros!$S$5:$S$30236,$B$4,Registros!$Q$5:$Q$30236,"CONCLUÍDO") -> 181.45306 | D17: =SUMIFS(Registros!$K$5:$K$30236,Registros!$G$5:$G$30236,B17,Registros!$D$5:$D$30236,"FDS/FERIADO",Registros!$S$5:$S$30236,$B$4,Registros!$Q$5:$Q$30236,"CONCLUÍDO") -> 0 | E17: =C17+D17 -> 181.45306 | F17: =COUNTIFS(Registros!$G$5:$G$30236,B17,Registros!$S$5:$S$30236,$B$4,Registros!$Q$5:$Q$30236,"CONCLUÍDO") -> 3 | G17: {=IF(F17=0,0,IFERROR(ROWS(_xlfn.UNIQUE(_xlfn._xlws.FILTER(Registros!$E$5:$E$30236,(Registros!$G$5:$G$30236=B17)*(Registros!$S$5:$S$30236=$B$4)*(Registros!$Q$5:$Q$30236="CONCLUÍDO")))),0))} -> 2 | H17: =SUMIFS(Registros!$P$5:$P$30236,Registros!$G$5:$G$30236,B17,Registros!$S$5:$S$30236,$B$4,Registros!$Q$5:$Q$30236,"CONCLUÍDO") -> 4264.08
A18: PRJ-004 | B18: OTEMPO | C18: =SUMIFS(Registros!$K$5:$K$30233,Registros!$G$5:$G$30233,B18,Registros!$D$5:$D$30233,"DIA ÚTIL",Registros!$S$5:$S$30233,$B$4,Registros!$Q$5:$Q$30233,"CONCLUÍDO") -> 67.230556 | D18: =SUMIFS(Registros!$K$5:$K$30233,Registros!$G$5:$G$30233,B18,Registros!$D$5:$D$30233,"FDS/FERIADO",Registros!$S$5:$S$30233,$B$4,Registros!$Q$5:$Q$30233,"CONCLUÍDO") -> 15.579722 | E18: =C18+D18 -> 82.810278 | F18: =COUNTIFS(Registros!$G$5:$G$30233,B18,Registros!$S$5:$S$30233,$B$4,Registros!$Q$5:$Q$30233,"CONCLUÍDO") -> 19 | G18: {=IF(F18=0,0,IFERROR(ROWS(_xlfn.UNIQUE(_xlfn._xlws.FILTER(Registros!$E$5:$E$30233,(Registros!$G$5:$G$30233=B18)*(Registros!$S$5:$S$30233=$B$4)*(Registros!$Q$5:$Q$30233="CONCLUÍDO")))),0))} -> 5 | H18: =SUMIFS(Registros!$P$5:$P$30233,Registros!$G$5:$G$30233,B18,Registros!$S$5:$S$30233,$B$4,Registros!$Q$5:$Q$30233,"CONCLUÍDO") -> 1635.1878
A19: PRJ-001 | B19: BC - CONFIANÇA PIX | C19: =SUMIFS(Registros!$K$5:$K$30232,Registros!$G$5:$G$30232,B19,Registros!$D$5:$D$30232,"DIA ÚTIL",Registros!$S$5:$S$30232,$B$4,Registros!$Q$5:$Q$30232,"CONCLUÍDO") -> 0 | D19: =SUMIFS(Registros!$K$5:$K$30232,Registros!$G$5:$G$30232,B19,Registros!$D$5:$D$30232,"FDS/FERIADO",Registros!$S$5:$S$30232,$B$4,Registros!$Q$5:$Q$30232,"CONCLUÍDO") -> 0 | E19: =C19+D19 -> 0 | F19: =COUNTIFS(Registros!$G$5:$G$30232,B19,Registros!$S$5:$S$30232,$B$4,Registros!$Q$5:$Q$30232,"CONCLUÍDO") -> 0 | G19: {=IF(F19=0,0,IFERROR(ROWS(_xlfn.UNIQUE(_xlfn._xlws.FILTER(Registros!$E$5:$E$30232,(Registros!$G$5:$G$30232=B19)*(Registros!$S$5:$S$30232=$B$4)*(Registros!$Q$5:$Q$30232="CONCLUÍDO")))),0))} -> 0 | H19: =SUMIFS(Registros!$P$5:$P$30232,Registros!$G$5:$G$30232,B19,Registros!$S$5:$S$30232,$B$4,Registros!$Q$5:$Q$30232,"CONCLUÍDO") -> 0
A20: PRJ-008 | B20: CAMPANHA | C20: =SUMIFS(Registros!$K$5:$K$30103,Registros!$G$5:$G$30103,B20,Registros!$D$5:$D$30103,"DIA ÚTIL",Registros!$S$5:$S$30103,$B$4,Registros!$Q$5:$Q$30103,"CONCLUÍDO") -> 0 | D20: =SUMIFS(Registros!$K$5:$K$30103,Registros!$G$5:$G$30103,B20,Registros!$D$5:$D$30103,"FDS/FERIADO",Registros!$S$5:$S$30103,$B$4,Registros!$Q$5:$Q$30103,"CONCLUÍDO") -> 0 | E20: =C20+D20 -> 0 | F20: =COUNTIFS(Registros!$G$5:$G$30103,B20,Registros!$S$5:$S$30103,$B$4,Registros!$Q$5:$Q$30103,"CONCLUÍDO") -> 0 | G20: {=IF(F20=0,0,IFERROR(ROWS(_xlfn.UNIQUE(_xlfn._xlws.FILTER(Registros!$E$5:$E$30103,(Registros!$G$5:$G$30103=B20)*(Registros!$S$5:$S$30103=$B$4)*(Registros!$Q$5:$Q$30103="CONCLUÍDO")))),0))} -> 0 | H20: =SUMIFS(Registros!$P$5:$P$30103,Registros!$G$5:$G$30103,B20,Registros!$S$5:$S$30103,$B$4,Registros!$Q$5:$Q$30103,"CONCLUÍDO") -> 0
A21: PRJ-011 | B21: BETIM - TRACKING | C21: =SUMIFS(Registros!$K$5:$K$30084,Registros!$G$5:$G$30084,B21,Registros!$D$5:$D$30084,"DIA ÚTIL",Registros!$S$5:$S$30084,$B$4,Registros!$Q$5:$Q$30084,"CONCLUÍDO") -> 0 | D21: =SUMIFS(Registros!$K$5:$K$30084,Registros!$G$5:$G$30084,B21,Registros!$D$5:$D$30084,"FDS/FERIADO",Registros!$S$5:$S$30084,$B$4,Registros!$Q$5:$Q$30084,"CONCLUÍDO") -> 0 | E21: =C21+D21 -> 0 | F21: =COUNTIFS(Registros!$G$5:$G$30084,B21,Registros!$S$5:$S$30084,$B$4,Registros!$Q$5:$Q$30084,"CONCLUÍDO") -> 0 | G21: {=IF(F21=0,0,IFERROR(ROWS(_xlfn.UNIQUE(_xlfn._xlws.FILTER(Registros!$E$5:$E$30084,(Registros!$G$5:$G$30084=B21)*(Registros!$S$5:$S$30084=$B$4)*(Registros!$Q$5:$Q$30084="CONCLUÍDO")))),0))} -> 0 | H21: =SUMIFS(Registros!$P$5:$P$30084,Registros!$G$5:$G$30084,B21,Registros!$S$5:$S$30084,$B$4,Registros!$Q$5:$Q$30084,"CONCLUÍDO") -> 0
A157: TOTAL | H157: =SUM(H7:H156) -> 12912.862

Sheet Configuração
A1: CONFIGURAÇÃO NO EXCEL DO SHAREPOINT
A2: Faça esta configuração uma única vez. Depois, os usuários utilizarão somente a aba Registrar Ponto.
A4: PASSO A PASSO
A6: 1 | B6: Envie este arquivo para uma biblioteca do SharePoint e abra no Excel para a Web.
A8: 2 | B8: Abra a aba Office Script, copie todas as linhas da coluna A a partir de A2.
A10: 3 | B10: No menu Automatizar, escolha Novo Script, apague o exemplo e cole o código copiado.
A12: 4 | B12: Salve o script com o nome Registrar Ponto DATATEMPO.
A14: 5 | B14: No painel do script, escolha Adicionar botão à planilha e posicione-o sobre o quadro laranja da aba Registrar Ponto.
A16: 6 | B16: Proteja as abas Batidas, Registros e resumos contra edição manual. Deixe os cadastros sob responsabilidade administrativa.
A18: 7 | B18: Compartilhe o arquivo. Cada usuário escolhe seu ID, tipo, projeto e atividade e clica no botão.
A22: IMPORTANTE: o botão precisa ser criado no Excel para a Web porque o script fica armazenado no ambiente Microsoft 365, não dentro do arquivo .xlsx. O arquivo já está preparado para receber o botão.
A26: PRIVACIDADE: após um INÍCIO ou FIM registrado com sucesso, o painel apaga automaticamente ID, tipo, projeto, atividade e observação. Em caso de erro, os campos permanecem para correção.
A30: PLANEJADO PARA 3 ANOS: até 100 pessoas, 150 projetos, 200 atividades e 30.000 jornadas nos resumos. Cadastre sempre dentro das tabelas e mantenha o status ATIVO. A primeira batida da nova pessoa/projeto cria automaticamente a linha correspondente nos resumos.

Sheet Office Script
A1: OFFICE SCRIPT — REGISTRAR PONTO
A2: function main(workbook: ExcelScript.Workbook) {
A3: const painel = workbook.getWorksheet("Registrar Ponto");
A4: const pessoas = workbook.getWorksheet("Cadastro Pessoas").getTable("tblPessoas");
A5: const projetos = workbook.getWorksheet("Cadastro Projetos").getTable("tblProjetos");
A6: const atividades = workbook.getWorksheet("Cadastro Atividades").getTable("tblAtividades");
A7: const batidas = workbook.getWorksheet("Batidas").getTable("tblBatidas");
A8: const registros = workbook.getWorksheet("Registros").getTable("tblRegistros");
A9: const id = String(painel.getRange("C6").getValue()).trim();
A10: const tipo = String(painel.getRange("C10").getValue()).trim().toUpperCase();
A11: const projeto = String(painel.getRange("C12").getValue()).trim();
A12: const atividade = String(painel.getRange("C14").getValue()).trim();
... A107: }
